Workbook

Sheet Overview
B2: Attendance & leave report
B3: 01–30 September 2026 · company overview
B5: Employees | C5: Employees | D5: Employees | F5: Present days | G5: Present days | H5: Present days | J5: PL taken (days) | K5: PL taken (days) | L5: PL taken (days) | N5: LWP (days) | O5: LWP (days)
B6: =SUM(C28:C37) -> 125 | F6: =SUM(E28:E37) -> 2476.5 | J6: =SUM(I28:I37) -> 178.5 | N6: =SUM(J28:J37) -> 91.5
B25: Company summary
B27: Company | C27: Employees | D27: Total Working Days | E27: Present | F27: Absent | G27: Half Day PL | H27: Full Day PL | I27: Total PL Taken | J27: LWP Taken | K27: Week Off | L27: Holiday | M27: September Opening Balance | N27: PL Taken (Ledger) | O27: Available Balance
B28: ALLUVIUM IOT SOLUTIONS PRIVATE LIMITED | C28: =COUNTIFS('Employee Summary'!$A$7:$A$131,B28) -> 2 | D28: =SUMIFS('Employee Summary'!$C$7:$C$131,'Employee Summary'!$A$7:$A$131,$B28) -> 30 | E28: =SUMIFS('Employee Summary'!$D$7:$D$131,'Employee Summary'!$A$7:$A$131,$B28) -> 21 | F28: =SUMIFS('Employee Summary'!$E$7:$E$131,'Employee Summary'!$A$7:$A$131,$B28) -> 26 | G28: =SUMIFS('Employee Summary'!$F$7:$F$131,'Employee Summary'!$A$7:$A$131,$B28) -> 0 | H28: =SUMIFS('Employee Summary'!$G$7:$G$131,'Employee Summary'!$A$7:$A$131,$B28) -> 2 | I28: =SUMIFS('Employee Summary'!$H$7:$H$131,'Employee Summary'!$A$7:$A$131,$B28) -> 2 | J28: =SUMIFS('Employee Summary'!$I$7:$I$131,'Employee Summary'!$A$7:$A$131,$B28) -> 4 | K28: =SUMIFS('Employee Summary'!$J$7:$J$131,'Employee Summary'!$A$7:$A$131,$B28) -> 6 | L28: =SUMIFS('Employee Summary'!$K$7:$K$131,'Employee Summary'!$A$7:$A$131,$B28) -> 1 | M28: =SUMIFS('Employee Summary'!$L$7:$L$131,'Employee Summary'!$A$7:$A$131,$B28) -> 10 | N28: =SUMIFS('Employee Summary'!$M$7:$M$131,'Employee Summary'!$A$7:$A$131,$B28) -> 2 | O28: =SUMIFS('Employee Summary'!$N$7:$N$131,'Employee Summary'!$A$7:$A$131,$B28) -> 8
B29: EXIMBIZ ENTERPRISE | C29: =COUNTIFS('Employee Summary'!$A$7:$A$131,B29) -> 8 | D29: =SUMIFS('Employee Summary'!$C$7:$C$131,'Employee Summary'!$A$7:$A$131,$B29) -> 240 | E29: =SUMIFS('Employee Summary'!$D$7:$D$131,'Employee Summary'!$A$7:$A$131,$B29) -> 181 | F29: =SUMIFS('Employee Summary'!$E$7:$E$131,'Employee Summary'!$A$7:$A$131,$B29) -> 0 | G29: =SUMIFS('Employee Summary'!$F$7:$F$131,'Employee Summary'!$A$7:$A$131,$B29) -> 8 | H29: =SUMIFS('Employee Summary'!$G$7:$G$131,'Employee Summary'!$A$7:$A$131,$B29) -> 8 | I29: =SUMIFS('Employee Summary'!$H$7:$H$131,'Employee Summary'!$A$7:$A$131,$B29) -> 12 | J29: =SUMIFS('Employee Summary'!$I$7:$I$131,'Employee Summary'!$A$7:$A$131,$B29) -> 0 | K29: =SUMIFS('Employee Summary'!$J$7:$J$131,'Employee Summary'!$A$7:$A$131,$B29) -> 39 | L29: =SUMIFS('Employee Summary'!$K$7:$K$131,'Employee Summary'!$A$7:$A$131,$B29) -> 8 | M29: =SUMIFS('Employee Summary'!$L$7:$L$131,'Employee Summary'!$A$7:$A$131,$B29) -> 124 | N29: =SUMIFS('Employee Summary'!$M$7:$M$131,'Employee Summary'!$A$7:$A$131,$B29) -> 12 | O29: =SUMIFS('Employee Summary'!$N$7:$N$131,'Employee Summary'!$A$7:$A$131,$B29) -> 112
B30: NOVUSHA CONSULTING SERVICES INDIA LLP | C30: =COUNTIFS('Employee Summary'!$A$7:$A$131,B30) -> 13 | D30: =SUMIFS('Employee Summary'!$C$7:$C$131,'Employee Summary'!$A$7:$A$131,$B30) -> 328 | E30: =SUMIFS('Employee Summary'!$D$7:$D$131,'Employee Summary'!$A$7:$A$131,$B30) -> 232 | F30: =SUMIFS('Employee Summary'!$E$7:$E$131,'Employee Summary'!$A$7:$A$131,$B30) -> 52 | G30: =SUMIFS('Employee Summary'!$F$7:$F$131,'Employee Summary'!$A$7:$A$131,$B30) -> 4 | H30: =SUMIFS('Employee Summary'!$G$7:$G$131,'Employee Summary'!$A$7:$A$131,$B30) -> 21 | I30: =SUMIFS('Employee Summary'!$H$7:$H$131,'Employee Summary'!$A$7:$A$131,$B30) -> 23 | J30: =SUMIFS('Employee Summary'!$I$7:$I$131,'Employee Summary'!$A$7:$A$131,$B30) -> 10 | K30: =SUMIFS('Employee Summary'!$J$7:$J$131,'Employee Summary'!$A$7:$A$131,$B30) -> 62 | L30: =SUMIFS('Employee Summary'!$K$7:$K$131,'Employee Summary'!$A$7:$A$131,$B30) -> 11 | M30: =SUMIFS('Employee Summary'!$L$7:$L$131,'Employee Summary'!$A$7:$A$131,$B30) -> 137 | N30: =SUMIFS('Employee Summary'!$M$7:$M$131,'Employee Summary'!$A$7:$A$131,$B30) -> 23 | O30: =SUMIFS('Employee Summary'!$N$7:$N$131,'Employee Summary'!$A$7:$A$131,$B30) -> 114
B31: PARAMOUNT PROPACK PRIVATE LIMITED | C31: =COUNTIFS('Employee Summary'!$A$7:$A$131,B31) -> 2 | D31: =SUMIFS('Employee Summary'!$C$7:$C$131,'Employee Summary'!$A$7:$A$131,$B31) -> 30 | E31: =SUMIFS('Employee Summary'!$D$7:$D$131,'Employee Summary'!$A$7:$A$131,$B31) -> 23 | F31: =SUMIFS('Employee Summary'!$E$7:$E$131,'Employee Summary'!$A$7:$A$131,$B31) -> 24 | G31: =SUMIFS('Employee Summary'!$F$7:$F$131,'Employee Summary'!$A$7:$A$131,$B31) -> 0 | H31: =SUMIFS('Employee Summary'!$G$7:$G$131,'Employee Summary'!$A$7:$A$131,$B31) -> 1 | I31: =SUMIFS('Employee Summary'!$H$7:$H$131,'Employee Summary'!$A$7:$A$131,$B31) -> 1 | J31: =SUMIFS('Employee Summary'!$I$7:$I$131,'Employee Summary'!$A$7:$A$131,$B31) -> 6 | K31: =SUMIFS('Employee Summary'!$J$7:$J$131,'Employee Summary'!$A$7:$A$131,$B31) -> 5 | L31: =SUMIFS('Employee Summary'!$K$7:$K$131,'Employee Summary'!$A$7:$A$131,$B31) -> 1 | M31: =SUMIFS('Employee Summary'!$L$7:$L$131,'Employee Summary'!$A$7:$A$131,$B31) -> 36.5 | N31: =SUMIFS('Employee Summary'!$M$7:$M$131,'Employee Summary'!$A$7:$A$131,$B31) -> 1 | O31: =SUMIFS('Employee Summary'!$N$7:$N$131,'Employee Summary'!$A$7:$A$131,$B31) -> 35.5
B32: SANSAR TRADELINK | C32: =COUNTIFS('Employee Summary'!$A$7:$A$131,B32) -> 11 | D32: =SUMIFS('Employee Summary'!$C$7:$C$131,'Employee Summary'!$A$7:$A$131,$B32) -> 327.5 | E32: =SUMIFS('Employee Summary'!$D$7:$D$131,'Employee Summary'!$A$7:$A$131,$B32) -> 242.5 | F32: =SUMIFS('Employee Summary'!$E$7:$E$131,'Employee Summary'!$A$7:$A$131,$B32) -> 0.5 | G32: =SUMIFS('Employee Summary'!$F$7:$F$131,'Employee Summary'!$A$7:$A$131,$B32) -> 2 | H32: =SUMIFS('Employee Summary'!$G$7:$G$131,'Employee Summary'!$A$7:$A$131,$B32) -> 23 | I32: =SUMIFS('Employee Summary'!$H$7:$H$131,'Employee Summary'!$A$7:$A$131,$B32) -> 24 | J32: =SUMIFS('Employee Summary'!$I$7:$I$131,'Employee Summary'!$A$7:$A$131,$B32) -> 2 | K32: =SUMIFS('Employee Summary'!$J$7:$J$131,'Employee Summary'!$A$7:$A$131,$B32) -> 53 | L32: =SUMIFS('Employee Summary'!$K$7:$K$131,'Employee Summary'!$A$7:$A$131,$B32) -> 8 | M32: =SUMIFS('Employee Summary'!$L$7:$L$131,'Employee Summary'!$A$7:$A$131,$B32) -> 198.5 | N32: =SUMIFS('Employee Summary'!$M$7:$M$131,'Employee Summary'!$A$7:$A$131,$B32) -> 24 | O32: =SUMIFS('Employee Summary'!$N$7:$N$131,'Employee Summary'!$A$7:$A$131,$B32) -> 174.5
B33: SR CONTAINER CARRIERS | C33: =COUNTIFS('Employee Summary'!$A$7:$A$131,B33) -> 19 | D33: =SUMIFS('Employee Summary'!$C$7:$C$131,'Employee Summary'!$A$7:$A$131,$B33) -> 515.5 | E33: =SUMIFS('Employee Summary'!$D$7:$D$131,'Employee Summary'!$A$7:$A$131,$B33) -> 400 | F33: =SUMIFS('Employee Summary'!$E$7:$E$131,'Employee Summary'!$A$7:$A$131,$B33) -> 31.5 | G33: =SUMIFS('Employee Summary'!$F$7:$F$131,'Employee Summary'!$A$7:$A$131,$B33) -> 1 | H33: =SUMIFS('Employee Summary'!$G$7:$G$131,'Employee Summary'!$A$7:$A$131,$B33) -> 22 | I33: =SUMIFS('Employee Summary'!$H$7:$H$131,'Employee Summary'!$A$7:$A$131,$B33) -> 22.5 | J33: =SUMIFS('Employee Summary'!$I$7:$I$131,'Employee Summary'!$A$7:$A$131,$B33) -> 13 | K33: =SUMIFS('Employee Summary'!$J$7:$J$131,'Employee Summary'!$A$7:$A$131,$B33) -> 79 | L33: =SUMIFS('Employee Summary'!$K$7:$K$131,'Employee Summary'!$A$7:$A$131,$B33) -> 14 | M33: =SUMIFS('Employee Summary'!$L$7:$L$131,'Employee Summary'!$A$7:$A$131,$B33) -> 403 | N33: =SUMIFS('Employee Summary'!$M$7:$M$131,'Employee Summary'!$A$7:$A$131,$B33) -> 22.5 | O33: =SUMIFS('Employee Summary'!$N$7:$N$131,'Employee Summary'!$A$7:$A$131,$B33) -> 380.5
B34: SURAJ FORWARDERS | C34: =COUNTIFS('Employee Summary'!$A$7:$A$131,B34) -> 7 | D34: =SUMIFS('Employee Summary'!$C$7:$C$131,'Employee Summary'!$A$7:$A$131,$B34) -> 205 | E34: =SUMIFS('Employee Summary'!$D$7:$D$131,'Employee Summary'!$A$7:$A$131,$B34) -> 161.5 | F34: =SUMIFS('Employee Summary'!$E$7:$E$131,'Employee Summary'!$A$7:$A$131,$B34) -> 0 | G34: =SUMIFS('Employee Summary'!$F$7:$F$131,'Employee Summary'!$A$7:$A$131,$B34) -> 3 | H34: =SUMIFS('Employee Summary'!$G$7:$G$131,'Employee Summary'!$A$7:$A$131,$B34) -> 1 | I34: =SUMIFS('Employee Summary'!$H$7:$H$131,'Employee Summary'!$A$7:$A$131,$B34) -> 2.5 | J34: =SUMIFS('Employee Summary'!$I$7:$I$131,'Employee Summary'!$A$7:$A$131,$B34) -> 5 | K34: =SUMIFS('Employee Summary'!$J$7:$J$131,'Employee Summary'!$A$7:$A$131,$B34) -> 34 | L34: =SUMIFS('Employee Summary'!$K$7:$K$131,'Employee Summary'!$A$7:$A$131,$B34) -> 7 | M34: =SUMIFS('Employee Summary'!$L$7:$L$131,'Employee Summary'!$A$7:$A$131,$B34) -> 109 | N34: =SUMIFS('Employee Summary'!$M$7:$M$131,'Employee Summary'!$A$7:$A$131,$B34) -> 2.5 | O34: =SUMIFS('Employee Summary'!$N$7:$N$131,'Employee Summary'!$A$7:$A$131,$B34) -> 106.5
B35: SURAJ FORWARDERS & SHIPPING AGENCIES | C35: =COUNTIFS('Employee Summary'!$A$7:$A$131,B35) -> 29 | D35: =SUMIFS('Employee Summary'!$C$7:$C$131,'Employee Summary'!$A$7:$A$131,$B35) -> 838.5 | E35: =SUMIFS('Employee Summary'!$D$7:$D$131,'Employee Summary'!$A$7:$A$131,$B35) -> 632.5 | F35: =SUMIFS('Employee Summary'!$E$7:$E$131,'Employee Summary'!$A$7:$A$131,$B35) -> 24.5 | G35: =SUMIFS('Employee Summary'!$F$7:$F$131,'Employee Summary'!$A$7:$A$131,$B35) -> 6 | H35: =SUMIFS('Employee Summary'!$G$7:$G$131,'Employee Summary'!$A$7:$A$131,$B35) -> 44 | I35: =SUMIFS('Employee Summary'!$H$7:$H$131,'Employee Summary'!$A$7:$A$131,$B35) -> 47 | J35: =SUMIFS('Employee Summary'!$I$7:$I$131,'Employee Summary'!$A$7:$A$131,$B35) -> 7 | K35: =SUMIFS('Employee Summary'!$J$7:$J$131,'Employee Summary'!$A$7:$A$131,$B35) -> 131 | L35: =SUMIFS('Employee Summary'!$K$7:$K$131,'Employee Summary'!$A$7:$A$131,$B35) -> 28 | M35: =SUMIFS('Employee Summary'!$L$7:$L$131,'Employee Summary'!$A$7:$A$131,$B35) -> 1250 | N35: =SUMIFS('Employee Summary'!$M$7:$M$131,'Employee Summary'!$A$7:$A$131,$B35) -> 47 | O35: =SUMIFS('Employee Summary'!$N$7:$N$131,'Employee Summary'!$A$7:$A$131,$B35) -> 1203
B36: SURAJ FORWARDERS PRIVATE LIMITED | C36: =COUNTIFS('Employee Summary'!$A$7:$A$131,B36) -> 28 | D36: =SUMIFS('Employee Summary'!$C$7:$C$131,'Employee Summary'!$A$7:$A$131,$B36) -> 774.5 | E36: =SUMIFS('Employee Summary'!$D$7:$D$131,'Employee Summary'!$A$7:$A$131,$B36) -> 583 | F36: =SUMIFS('Employee Summary'!$E$7:$E$131,'Employee Summary'!$A$7:$A$131,$B36) -> 50 | G36: =SUMIFS('Employee Summary'!$F$7:$F$131,'Employee Summary'!$A$7:$A$131,$B36) -> 3 | H36: =SUMIFS('Employee Summary'!$G$7:$G$131,'Employee Summary'!$A$7:$A$131,$B36) -> 43 | I36: =SUMIFS('Employee Summary'!$H$7:$H$131,'Employee Summary'!$A$7:$A$131,$B36) -> 44.5 | J36: =SUMIFS('Employee Summary'!$I$7:$I$131,'Employee Summary'!$A$7:$A$131,$B36) -> 14.5 | K36: =SUMIFS('Employee Summary'!$J$7:$J$131,'Employee Summary'!$A$7:$A$131,$B36) -> 123 | L36: =SUMIFS('Employee Summary'!$K$7:$K$131,'Employee Summary'!$A$7:$A$131,$B36) -> 24 | M36: =SUMIFS('Employee Summary'!$L$7:$L$131,'Employee Summary'!$A$7:$A$131,$B36) -> 825 | N36: =SUMIFS('Employee Summary'!$M$7:$M$131,'Employee Summary'!$A$7:$A$131,$B36) -> 44.5 | O36: =SUMIFS('Employee Summary'!$N$7:$N$131,'Employee Summary'!$A$7:$A$131,$B36) -> 780.5
B37: UNASSIGNED | C37: =COUNTIFS('Employee Summary'!$A$7:$A$131,B37) -> 6 | D37: =SUMIFS('Employee Summary'!$C$7:$C$131,'Employee Summary'!$A$7:$A$131,$B37) -> 0 | E37: =SUMIFS('Employee Summary'!$D$7:$D$131,'Employee Summary'!$A$7:$A$131,$B37) -> 0 | F37: =SUMIFS('Employee Summary'!$E$7:$E$131,'Employee Summary'!$A$7:$A$131,$B37) -> 150 | G37: =SUMIFS('Employee Summary'!$F$7:$F$131,'Employee Summary'!$A$7:$A$131,$B37) -> 0 | H37: =SUMIFS('Employee Summary'!$G$7:$G$131,'Employee Summary'!$A$7:$A$131,$B37) -> 0 | I37: =SUMIFS('Employee Summary'!$H$7:$H$131,'Employee Summary'!$A$7:$A$131,$B37) -> 0 | J37: =SUMIFS('Employee Summary'!$I$7:$I$131,'Employee Summary'!$A$7:$A$131,$B37) -> 30 | K37: =SUMIFS('Employee Summary'!$J$7:$J$131,'Employee Summary'!$A$7:$A$131,$B37) -> 0 | L37: =SUMIFS('Employee Summary'!$K$7:$K$131,'Employee Summary'!$A$7:$A$131,$B37) -> 0 | M37: =SUMIFS('Employee Summary'!$L$7:$L$131,'Employee Summary'!$A$7:$A$131,$B37) -> 72 | N37: =SUMIFS('Employee Summary'!$M$7:$M$131,'Employee Summary'!$A$7:$A$131,$B37) -> 0 | O37: =SUMIFS('Employee Summary'!$N$7:$N$131,'Employee Summary'!$A$7:$A$131,$B37) -> 72
B38: Total | C38: =SUM(C28:C37) -> 125 | D38: =SUM(D28:D37) -> 3289 | E38: =SUM(E28:E37) -> 2476.5 | F38: =SUM(F28:F37) -> 358.5 | G38: =SUM(G28:G37) -> 27 | H38: =SUM(H28:H37) -> 165 | I38: =SUM(I28:I37) -> 178.5 | J38: =SUM(J28:J37) -> 91.5 | ... O38: =SUM(O28:O37) -> 2986.5
B40: Total Working Days follows the source label and includes paid leave, weekly offs and holidays. Half Day PL counts occurrences; PL quantities use days.
B41: Attendance PL taken and ledger PL taken remain separate. The Employee Summary retains each supplied average-hours value.
B42: The source has two incomplete employee calendar totals. Rounded daily hours also differ from supplied footers by nine minutes; the original figures are retained.
B44: Chart data
B45: Company label | C45: Employees | D45: PL days | E45: LWP days | G45: =B45 -> Company label | H45: =D45 -> PL days | I45: =E45 -> LWP days
B46: Suraj Ship | C46: =C35 -> 29 | D46: =I35 -> 47 | E46: =J35 -> 7 | G46: =B46 -> Suraj Ship | H46: =D46 -> 47 | I46: =E46 -> 7
B47: Suraj Pvt | C47: =C36 -> 28 | D47: =I36 -> 44.5 | E47: =J36 -> 14.5 | G47: =B47 -> Suraj Pvt | H47: =D47 -> 44.5 | I47: =E47 -> 14.5
B48: SRCC | C48: =C33 -> 19 | D48: =I33 -> 22.5 | E48: =J33 -> 13 | G48: =B48 -> SRCC | H48: =D48 -> 22.5 | I48: =E48 -> 13
B49: Novusha | C49: =C30 -> 13 | D49: =I30 -> 23 | E49: =J30 -> 10 | G49: =B49 -> Novusha | H49: =D49 -> 23 | I49: =E49 -> 10
B50: Sansar | C50: =C32 -> 11 | D50: =I32 -> 24 | E50: =J32 -> 2 | G50: =B50 -> Sansar | H50: =D50 -> 24 | I50: =E50 -> 2
B51: Eximbiz | C51: =C29 -> 8 | D51: =I29 -> 12 | E51: =J29 -> 0 | G51: =B51 -> Eximbiz | H51: =D51 -> 12 | I51: =E51 -> 0
B52: Suraj | C52: =C34 -> 7 | D52: =I34 -> 2.5 | E52: =J34 -> 5 | G52: =B52 -> Suraj | H52: =D52 -> 2.5 | I52: =E52 -> 5
B53: Unassigned | C53: =C37 -> 6 | D53: =I37 -> 0 | E53: =J37 -> 30 | G53: =B53 -> Unassigned | H53: =D53 -> 0 | I53: =E53 -> 30
B54: Alluvium | C54: =C28 -> 2 | D54: =I28 -> 2 | E54: =J28 -> 4 | G54: =B54 -> Alluvium | H54: =D54 -> 2 | I54: =E54 -> 4
B55: Paramount | C55: =C31 -> 2 | D55: =I31 -> 1 | E55: =J31 -> 6 | G55: =B55 -> Paramount | H55: =D55 -> 1 | I55: =E55 -> 6

Sheet Employee Summary
A2: Attendance & leave — employee summary
A3: 01–30 September 2026 · 125 employees · all companies
A4: Source: AttendanceReport_2026-09-01_to_2026-09-30.xlsx. Original company registers follow these summary tabs.
A6: Company | B6: Employee | C6: Total Working Days | D6: Present | E6: Absent | F6: Half Day PL | G6: Full Day PL | H6: Total PL Taken | I6: LWP Taken | J6: Week Off | K6: Holiday | L6: September Opening Balance | M6: PL Taken (Ledger) | N6: Available Balance | O6: Avg Hours/Day
A7: ="ALLUVIUM IOT SOLUTIONS PRIVATE LIMITED" -> ALLUVIUM IOT SOLUTIONS PRIVATE LIMITED | B7: ='Alluvium IoT Solutions Private '!A5 -> ARPIT SINGHAL | C7: ='Alluvium IoT Solutions Private '!B5 -> 0 | D7: ='Alluvium IoT Solutions Private '!C5 -> 0 | E7: ='Alluvium IoT Solutions Private '!D5 -> 26 | F7: ='Alluvium IoT Solutions Private '!E5 -> 0 | G7: ='Alluvium IoT Solutions Private '!F5 -> 0 | H7: ='Alluvium IoT Solutions Private '!G5 -> 0 | I7: ='Alluvium IoT Solutions Private '!H5 -> 4 | ... K7: ='Alluvium IoT Solutions Private '!J5 -> 0 | L7: ='Alluvium IoT Solutions Private '!M5 -> 0 | M7: ='Alluvium IoT Solutions Private '!N5 -> 0 | N7: ='Alluvium IoT Solutions Private '!O5 -> 0 | O7: ='Alluvium IoT Solutions Private '!P5 -> 0h 0m
A8: ="ALLUVIUM IOT SOLUTIONS PRIVATE LIMITED" -> ALLUVIUM IOT SOLUTIONS PRIVATE LIMITED | B8: ='Alluvium IoT Solutions Private '!A6 -> MASOOD RAZA | C8: ='Alluvium IoT Solutions Private '!B6 -> 30 | D8: ='Alluvium IoT Solutions Private '!C6 -> 21 | E8: ='Alluvium IoT Solutions Private '!D6 -> 0 | F8: ='Alluvium IoT Solutions Private '!E6 -> 0 | G8: ='Alluvium IoT Solutions Private '!F6 -> 2 | H8: ='Alluvium IoT Solutions Private '!G6 -> 2 | I8: ='Alluvium IoT Solutions Private '!H6 -> 0 | ... K8: ='Alluvium IoT Solutions Private '!J6 -> 1 | L8: ='Alluvium IoT Solutions Private '!M6 -> 10 | M8: ='Alluvium IoT Solutions Private '!N6 -> 2 | N8: ='Alluvium IoT Solutions Private '!O6 -> 8 | O8: ='Alluvium IoT Solutions Private '!P6 -> 9h 48m
A9: ="EXIMBIZ ENTERPRISE" -> EXIMBIZ ENTERPRISE | B9: ='Eximbiz Enterprise'!A5 -> AHMED ADENWALA | C9: ='Eximbiz Enterprise'!B5 -> 30 | D9: ='Eximbiz Enterprise'!C5 -> 23.5 | E9: ='Eximbiz Enterprise'!D5 -> 0 | F9: ='Eximbiz Enterprise'!E5 -> 1 | G9: ='Eximbiz Enterprise'!F5 -> 0 | H9: ='Eximbiz Enterprise'!G5 -> 0.5 | I9: ='Eximbiz Enterprise'!H5 -> 0 | ... K9: ='Eximbiz Enterprise'!J5 -> 1 | L9: ='Eximbiz Enterprise'!M5 -> 35.5 | M9: ='Eximbiz Enterprise'!N5 -> 0.5 | N9: ='Eximbiz Enterprise'!O5 -> 35 | O9: ='Eximbiz Enterprise'!P5 -> 9h 12m
A10: ="EXIMBIZ ENTERPRISE" -> EXIMBIZ ENTERPRISE | B10: ='Eximbiz Enterprise'!A6 -> ALPESH PARMAR | C10: ='Eximbiz Enterprise'!B6 -> 30 | D10: ='Eximbiz Enterprise'!C6 -> 20 | E10: ='Eximbiz Enterprise'!D6 -> 0 | F10: ='Eximbiz Enterprise'!E6 -> 2 | G10: ='Eximbiz Enterprise'!F6 -> 3 | H10: ='Eximbiz Enterprise'!G6 -> 4 | I10: ='Eximbiz Enterprise'!H6 -> 0 | ... K10: ='Eximbiz Enterprise'!J6 -> 1 | L10: ='Eximbiz Enterprise'!M6 -> 24.5 | M10: ='Eximbiz Enterprise'!N6 -> 4 | N10: ='Eximbiz Enterprise'!O6 -> 20.5 | O10: ='Eximbiz Enterprise'!P6 -> 9h 0m
A11: ="EXIMBIZ ENTERPRISE" -> EXIMBIZ ENTERPRISE | B11: ='Eximbiz Enterprise'!A7 -> AMBILY | C11: ='Eximbiz Enterprise'!B7 -> 30 | D11: ='Eximbiz Enterprise'!C7 -> 24 | E11: ='Eximbiz Enterprise'!D7 -> 0 | F11: ='Eximbiz Enterprise'!E7 -> 0 | G11: ='Eximbiz Enterprise'!F7 -> 0 | H11: ='Eximbiz Enterprise'!G7 -> 0 | I11: ='Eximbiz Enterprise'!H7 -> 0 | ... K11: ='Eximbiz Enterprise'!J7 -> 1 | L11: ='Eximbiz Enterprise'!M7 -> 0 | M11: ='Eximbiz Enterprise'!N7 -> 0 | N11: ='Eximbiz Enterprise'!O7 -> 0 | O11: ='Eximbiz Enterprise'!P7 -> 9h 0m
A12: ="EXIMBIZ ENTERPRISE" -> EXIMBIZ ENTERPRISE | B12: ='Eximbiz Enterprise'!A8 -> DIPAK VAGHELA | C12: ='Eximbiz Enterprise'!B8 -> 30 | D12: ='Eximbiz Enterprise'!C8 -> 20.5 | E12: ='Eximbiz Enterprise'!D8 -> 0 | F12: ='Eximbiz Enterprise'!E8 -> 5 | G12: ='Eximbiz Enterprise'!F8 -> 2 | H12: ='Eximbiz Enterprise'!G8 -> 4.5 | I12: ='Eximbiz Enterprise'!H8 -> 0 | ... K12: ='Eximbiz Enterprise'!J8 -> 1 | L12: ='Eximbiz Enterprise'!M8 -> 16 | M12: ='Eximbiz Enterprise'!N8 -> 4.5 | N12: ='Eximbiz Enterprise'!O8 -> 11.5 | O12: ='Eximbiz Enterprise'!P8 -> 9h 30m
A13: ="EXIMBIZ ENTERPRISE" -> EXIMBIZ ENTERPRISE | B13: ='Eximbiz Enterprise'!A9 -> HIRANRAJ R | C13: ='Eximbiz Enterprise'!B9 -> 30 | D13: ='Eximbiz Enterprise'!C9 -> 24 | E13: ='Eximbiz Enterprise'!D9 -> 0 | F13: ='Eximbiz Enterprise'!E9 -> 0 | G13: ='Eximbiz Enterprise'!F9 -> 0 | H13: ='Eximbiz Enterprise'!G9 -> 0 | I13: ='Eximbiz Enterprise'!H9 -> 0 | ... K13: ='Eximbiz Enterprise'!J9 -> 1 | L13: ='Eximbiz Enterprise'!M9 -> 0 | M13: ='Eximbiz Enterprise'!N9 -> 0 | N13: ='Eximbiz Enterprise'!O9 -> 0 | O13: ='Eximbiz Enterprise'!P9 -> 9h 6m
A14: ="EXIMBIZ ENTERPRISE" -> EXIMBIZ ENTERPRISE | B14: ='Eximbiz Enterprise'!A10 -> KARAN MISHRA | C14: ='Eximbiz Enterprise'!B10 -> 30 | D14: ='Eximbiz Enterprise'!C10 -> 22 | E14: ='Eximbiz Enterprise'!D10 -> 0 | F14: ='Eximbiz Enterprise'!E10 -> 0 | G14: ='Eximbiz Enterprise'!F10 -> 2 | H14: ='Eximbiz Enterprise'!G10 -> 2 | I14: ='Eximbiz Enterprise'!H10 -> 0 | ... K14: ='Eximbiz Enterprise'!J10 -> 1 | L14: ='Eximbiz Enterprise'!M10 -> 17 | M14: ='Eximbiz Enterprise'!N10 -> 2 | N14: ='Eximbiz Enterprise'!O10 -> 15 | O14: ='Eximbiz Enterprise'!P10 -> 9h 6m
A15: ="EXIMBIZ ENTERPRISE" -> EXIMBIZ ENTERPRISE | B15: ='Eximbiz Enterprise'!A11 -> RAHUL SOLANKI | C15: ='Eximbiz Enterprise'!B11 -> 30 | D15: ='Eximbiz Enterprise'!C11 -> 23 | E15: ='Eximbiz Enterprise'!D11 -> 0 | F15: ='Eximbiz Enterprise'!E11 -> 0 | G15: ='Eximbiz Enterprise'!F11 -> 1 | H15: ='Eximbiz Enterprise'!G11 -> 1 | I15: ='Eximbiz Enterprise'!H11 -> 0 | ... K15: ='Eximbiz Enterprise'!J11 -> 1 | L15: ='Eximbiz Enterprise'!M11 -> 31 | M15: ='Eximbiz Enterprise'!N11 -> 1 | N15: ='Eximbiz Enterprise'!O11 -> 30 | O15: ='Eximbiz Enterprise'!P11 -> 9h 6m
A16: ="EXIMBIZ ENTERPRISE" -> EXIMBIZ ENTERPRISE | B16: ='Eximbiz Enterprise'!A12 -> RENUKA SONAVANE | C16: ='Eximbiz Enterprise'!B12 -> 30 | D16: ='Eximbiz Enterprise'!C12 -> 24 | E16: ='Eximbiz Enterprise'!D12 -> 0 | F16: ='Eximbiz Enterprise'!E12 -> 0 | G16: ='Eximbiz Enterprise'!F12 -> 0 | H16: ='Eximbiz Enterprise'!G12 -> 0 | I16: ='Eximbiz Enterprise'!H12 -> 0 | ... K16: ='Eximbiz Enterprise'!J12 -> 1 | L16: ='Eximbiz Enterprise'!M12 -> 0 | M16: ='Eximbiz Enterprise'!N12 -> 0 | N16: ='Eximbiz Enterprise'!O12 -> 0 | O16: ='Eximbiz Enterprise'!P12 -> 9h 24m
A17: ="NOVUSHA CONSULTING SERVICES INDIA LLP" -> NOVUSHA CONSULTING SERVICES INDIA LLP | B17: ='Novusha Consulting Services Ind'!A5 -> ANUBHAV SINGH | C17: ='Novusha Consulting Services Ind'!B5 -> 29 | D17: ='Novusha Consulting Services Ind'!C5 -> 22 | E17: ='Novusha Consulting Services Ind'!D5 -> 0 | F17: ='Novusha Consulting Services Ind'!E5 -> 0 | G17: ='Novusha Consulting Services Ind'!F5 -> 0 | H17: ='Novusha Consulting Services Ind'!G5 -> 0 | I17: ='Novusha Consulting Services Ind'!H5 -> 1 | ... K17: ='Novusha Consulting Services Ind'!J5 -> 1 | L17: ='Novusha Consulting Services Ind'!M5 -> 17 | M17: ='Novusha Consulting Services Ind'!N5 -> 0 | N17: ='Novusha Consulting Services Ind'!O5 -> 17 | O17: ='Novusha Consulting Services Ind'!P5 -> 9h 6m
A18: ="NOVUSHA CONSULTING SERVICES INDIA LLP" -> NOVUSHA CONSULTING SERVICES INDIA LLP | B18: ='Novusha Consulting Services Ind'!A6 -> ATUL NAGOSE | C18: ='Novusha Consulting Services Ind'!B6 -> 30 | D18: ='Novusha Consulting Services Ind'!C6 -> 22 | E18: ='Novusha Consulting Services Ind'!D6 -> 0 | F18: ='Novusha Consulting Services Ind'!E6 -> 0 | G18: ='Novusha Consulting Services Ind'!F6 -> 1 | H18: ='Novusha Consulting Services Ind'!G6 -> 1 | I18: ='Novusha Consulting Services Ind'!H6 -> 0 | ... K18: ='Novusha Consulting Services Ind'!J6 -> 1 | L18: ='Novusha Consulting Services Ind'!M6 -> 20.5 | M18: ='Novusha Consulting Services Ind'!N6 -> 1 | N18: ='Novusha Consulting Services Ind'!O6 -> 19.5 | O18: ='Novusha Consulting Services Ind'!P6 -> 9h 0m
A19: ="NOVUSHA CONSULTING SERVICES INDIA LLP" -> NOVUSHA CONSULTING SERVICES INDIA LLP | B19: ='Novusha Consulting Services Ind'!A7 -> JAGDISH PUROHIT | C19: ='Novusha Consulting Services Ind'!B7 -> 30 | D19: ='Novusha Consulting Services Ind'!C7 -> 12 | E19: ='Novusha Consulting Services Ind'!D7 -> 0 | F19: ='Novusha Consulting Services Ind'!E7 -> 0 | G19: ='Novusha Consulting Services Ind'!F7 -> 14 | H19: ='Novusha Consulting Services Ind'!G7 -> 14 | I19: ='Novusha Consulting Services Ind'!H7 -> 0 | ... K19: ='Novusha Consulting Services Ind'!J7 -> 1 | L19: ='Novusha Consulting Services Ind'!M7 -> 14 | M19: ='Novusha Consulting Services Ind'!N7 -> 14 | N19: ='Novusha Consulting Services Ind'!O7 -> 0 | O19: ='Novusha Consulting Services Ind'!P7 -> 8h 48m
A20: ="NOVUSHA CONSULTING SERVICES INDIA LLP" -> NOVUSHA CONSULTING SERVICES INDIA LLP | B20: ='Novusha Consulting Services Ind'!A8 -> KINJAL KHATRI | C20: ='Novusha Consulting Services Ind'!B8 -> 30 | D20: ='Novusha Consulting Services Ind'!C8 -> 22 | E20: ='Novusha Consulting Services Ind'!D8 -> 0 | F20: ='Novusha Consulting Services Ind'!E8 -> 0 | G20: ='Novusha Consulting Services Ind'!F8 -> 1 | H20: ='Novusha Consulting Services Ind'!G8 -> 1 | I20: ='Novusha Consulting Services Ind'!H8 -> 0 | ... K20: ='Novusha Consulting Services Ind'!J8 -> 1 | L20: ='Novusha Consulting Services Ind'!M8 -> 17.5 | M20: ='Novusha Consulting Services Ind'!N8 -> 1 | N20: ='Novusha Consulting Services Ind'!O8 -> 16.5 | O20: ='Novusha Consulting Services Ind'!P8 -> 9h 0m
A21: ="NOVUSHA CONSULTING SERVICES INDIA LLP" -> NOVUSHA CONSULTING SERVICES INDIA LLP | B21: ='Novusha Consulting Services Ind'!A9 -> KRUPALI BUSA | C21: ='Novusha Consulting Services Ind'!B9 -> 30 | D21: ='Novusha Consulting Services Ind'!C9 -> 22 | E21: ='Novusha Consulting Services Ind'!D9 -> 0 | F21: ='Novusha Consulting Services Ind'!E9 -> 0 | G21: ='Novusha Consulting Services Ind'!F9 -> 1 | H21: ='Novusha Consulting Services Ind'!G9 -> 1 | I21: ='Novusha Consulting Services Ind'!H9 -> 0 | ... K21: ='Novusha Consulting Services Ind'!J9 -> 1 | L21: ='Novusha Consulting Services Ind'!M9 -> 13 | M21: ='Novusha Consulting Services Ind'!N9 -> 1 | N21: ='Novusha Consulting Services Ind'!O9 -> 12 | O21: ='Novusha Consulting Services Ind'!P9 -> 9h 0m
A22: ="NOVUSHA CONSULTING SERVICES INDIA LLP" -> NOVUSHA CONSULTING SERVICES INDIA LLP | B22: ='Novusha Consulting Services Ind'!A10 -> NIRALI SHAH | C22: ='Novusha Consulting Services Ind'!B10 -> 0 | D22: ='Novusha Consulting Services Ind'!C10 -> 0 | E22: ='Novusha Consulting Services Ind'!D10 -> 26 | F22: ='Novusha Consulting Services Ind'!E10 -> 0 | G22: ='Novusha Consulting Services Ind'!F10 -> 0 | H22: ='Novusha Consulting Services Ind'!G10 -> 0 | I22: ='Novusha Consulting Services Ind'!H10 -> 4 | ... K22: ='Novusha Consulting Services Ind'!J10 -> 0 | L22: ='Novusha Consulting Services Ind'!M10 -> 0 | M22: ='Novusha Consulting Services Ind'!N10 -> 0 | N22: ='Novusha Consulting Services Ind'!O10 -> 0 | O22: ='Novusha Consulting Services Ind'!P10 -> 0h 0m
A23: ="NOVUSHA CONSULTING SERVICES INDIA LLP" -> NOVUSHA CONSULTING SERVICES INDIA LLP | B23: ='Novusha Consulting Services Ind'!A11 -> PRADEEP KUMAR SINGH | C23: ='Novusha Consulting Services Ind'!B11 -> 30 | D23: ='Novusha Consulting Services Ind'!C11 -> 23 | E23: ='Novusha Consulting Services Ind'!D11 -> 0 | F23: ='Novusha Consulting Services Ind'!E11 -> 0 | G23: ='Novusha Consulting Services Ind'!F11 -> 0 | H23: ='Novusha Consulting Services Ind'!G11 -> 0 | I23: ='Novusha Consulting Services Ind'!H11 -> 0 | ... K23: ='Novusha Consulting Services Ind'!J11 -> 1 | L23: ='Novusha Consulting Services Ind'!M11 -> 0 | M23: ='Novusha Consulting Services Ind'!N11 -> 0 | N23: ='Novusha Consulting Services Ind'!O11 -> 0 | O23: ='Novusha Consulting Services Ind'!P11 -> 9h 18m
A24: ="NOVUSHA CONSULTING SERVICES INDIA LLP" -> NOVUSHA CONSULTING SERVICES INDIA LLP | B24: ='Novusha Consulting Services Ind'!A12 -> PUNIT PANDEY | C24: ='Novusha Consulting Services Ind'!B12 -> 30 | D24: ='Novusha Consulting Services Ind'!C12 -> 23 | E24: ='Novusha Consulting Services Ind'!D12 -> 0 | F24: ='Novusha Consulting Services Ind'!E12 -> 0 | G24: ='Novusha Consulting Services Ind'!F12 -> 1 | H24: ='Novusha Consulting Services Ind'!G12 -> 1 | I24: ='Novusha Consulting Services Ind'!H12 -> 0 | ... K24: ='Novusha Consulting Services Ind'!J12 -> 1 | L24: ='Novusha Consulting Services Ind'!M12 -> 13 | M24: ='Novusha Consulting Services Ind'!N12 -> 1 | N24: ='Novusha Consulting Services Ind'!O12 -> 12 | O24: ='Novusha Consulting Services Ind'!P12 -> 9h 12m
A25: ="NOVUSHA CONSULTING SERVICES INDIA LLP" -> NOVUSHA CONSULTING SERVICES INDIA LLP | B25: ='Novusha Consulting Services Ind'!A13 -> RAUF DAYMA | C25: ='Novusha Consulting Services Ind'!B13 -> 30 | D25: ='Novusha Consulting Services Ind'!C13 -> 23 | E25: ='Novusha Consulting Services Ind'!D13 -> 0 | F25: ='Novusha Consulting Services Ind'!E13 -> 0 | G25: ='Novusha Consulting Services Ind'!F13 -> 0 | H25: ='Novusha Consulting Services Ind'!G13 -> 0 | I25: ='Novusha Consulting Services Ind'!H13 -> 0 | ... K25: ='Novusha Consulting Services Ind'!J13 -> 1 | L25: ='Novusha Consulting Services Ind'!M13 -> 23 | M25: ='Novusha Consulting Services Ind'!N13 -> 0 | N25: ='Novusha Consulting Services Ind'!O13 -> 23 | O25: ='Novusha Consulting Services Ind'!P13 -> 9h 12m
A26: ="NOVUSHA CONSULTING SERVICES INDIA LLP" -> NOVUSHA CONSULTING SERVICES INDIA LLP | B26: ='Novusha Consulting Services Ind'!A14 -> RIYA SAINI | C26: ='Novusha Consulting Services Ind'!B14 -> 0 | D26: ='Novusha Consulting Services Ind'!C14 -> 0 | E26: ='Novusha Consulting Services Ind'!D14 -> 26 | F26: ='Novusha Consulting Services Ind'!E14 -> 0 | G26: ='Novusha Consulting Services Ind'!F14 -> 0 | H26: ='Novusha Consulting Services Ind'!G14 -> 0 | I26: ='Novusha Consulting Services Ind'!H14 -> 4 | ... K26: ='Novusha Consulting Services Ind'!J14 -> 0 | L26: ='Novusha Consulting Services Ind'!M14 -> 0 | M26: ='Novusha Consulting Services Ind'!N14 -> 0 | N26: ='Novusha Consulting Services Ind'!O14 -> 0 | O26: ='Novusha Consulting Services Ind'!P14 -> 0h 0m
A27: ="NOVUSHA CONSULTING SERVICES INDIA LLP" -> NOVUSHA CONSULTING SERVICES INDIA LLP | B27: ='Novusha Consulting Services Ind'!A15 -> SAIF ANSARI | C27: ='Novusha Consulting Services Ind'!B15 -> 29 | D27: ='Novusha Consulting Services Ind'!C15 -> 22 | E27: ='Novusha Consulting Services Ind'!D15 -> 0 | F27: ='Novusha Consulting Services Ind'!E15 -> 0 | G27: ='Novusha Consulting Services Ind'!F15 -> 0 | H27: ='Novusha Consulting Services Ind'!G15 -> 0 | I27: ='Novusha Consulting Services Ind'!H15 -> 1 | ... K27: ='Novusha Consulting Services Ind'!J15 -> 1 | L27: ='Novusha Consulting Services Ind'!M15 -> 0 | M27: ='Novusha Consulting Services Ind'!N15 -> 0 | N27: ='Novusha Consulting Services Ind'!O15 -> 0 | O27: ='Novusha Consulting Services Ind'!P15 -> 8h 54m
A28: ="NOVUSHA CONSULTING SERVICES INDIA LLP" -> NOVUSHA CONSULTING SERVICES INDIA LLP | B28: ='Novusha Consulting Services Ind'!A16 -> SHIPRA TRIPATHI | C28: ='Novusha Consulting Services Ind'!B16 -> 30 | D28: ='Novusha Consulting Services Ind'!C16 -> 22 | E28: ='Novusha Consulting Services Ind'!D16 -> 0 | F28: ='Novusha Consulting Services Ind'!E16 -> 2 | G28: ='Novusha Consulting Services Ind'!F16 -> 0 | H28: ='Novusha Consulting Services Ind'!G16 -> 1 | I28: ='Novusha Consulting Services Ind'!H16 -> 0 | ... K28: ='Novusha Consulting Services Ind'!J16 -> 1 | L28: ='Novusha Consulting Services Ind'!M16 -> 8 | M28: ='Novusha Consulting Services Ind'!N16 -> 1 | N28: ='Novusha Consulting Services Ind'!O16 -> 7 | O28: ='Novusha Consulting Services Ind'!P16 -> 9h 6m
A29: ="NOVUSHA CONSULTING SERVICES INDIA LLP" -> NOVUSHA CONSULTING SERVICES INDIA LLP | B29: ='Novusha Consulting Services Ind'!A17 -> YASH GUPTA | C29: ='Novusha Consulting Services Ind'!B17 -> 30 | D29: ='Novusha Consulting Services Ind'!C17 -> 19 | E29: ='Novusha Consulting Services Ind'!D17 -> 0 | F29: ='Novusha Consulting Services Ind'!E17 -> 2 | G29: ='Novusha Consulting Services Ind'!F17 -> 3 | H29: ='Novusha Consulting Services Ind'!G17 -> 4 | I29: ='Novusha Consulting Services Ind'!H17 -> 0 | ... K29: ='Novusha Consulting Services Ind'!J17 -> 1 | L29: ='Novusha Consulting Services Ind'!M17 -> 11 | M29: ='Novusha Consulting Services Ind'!N17 -> 4 | N29: ='Novusha Consulting Services Ind'!O17 -> 7 | O29: ='Novusha Consulting Services Ind'!P17 -> 9h 12m
A30: ="PARAMOUNT PROPACK PRIVATE LIMITED" -> PARAMOUNT PROPACK PRIVATE LIMITED | B30: ='Paramount Propack Private Limit'!A5 -> KRISHNAPAL PUVAR | C30: ='Paramount Propack Private Limit'!B5 -> 0 | D30: ='Paramount Propack Private Limit'!C5 -> 0 | E30: ='Paramount Propack Private Limit'!D5 -> 24 | F30: ='Paramount Propack Private Limit'!E5 -> 0 | G30: ='Paramount Propack Private Limit'!F5 -> 0 | H30: ='Paramount Propack Private Limit'!G5 -> 0 | I30: ='Paramount Propack Private Limit'!H5 -> 6 | ... K30: ='Paramount Propack Private Limit'!J5 -> 0 | L30: ='Paramount Propack Private Limit'!M5 -> 18.5 | M30: ='Paramount Propack Private Limit'!N5 -> 0 | N30: ='Paramount Propack Private Limit'!O5 -> 18.5 | O30: ='Paramount Propack Private Limit'!P5 -> 0h 0m
A31: ="PARAMOUNT PROPACK PRIVATE LIMITED" -> PARAMOUNT PROPACK PRIVATE LIMITED | B31: ='Paramount Propack Private Limit'!A6 -> PRATIK SAKRECHA | C31: ='Paramount Propack Private Limit'!B6 -> 30 | D31: ='Paramount Propack Private Limit'!C6 -> 23 | E31: ='Paramount Propack Private Limit'!D6 -> 0 | F31: ='Paramount Propack Private Limit'!E6 -> 0 | G31: ='Paramount Propack Private Limit'!F6 -> 1 | H31: ='Paramount Propack Private Limit'!G6 -> 1 | I31: ='Paramount Propack Private Limit'!H6 -> 0 | ... K31: ='Paramount Propack Private Limit'!J6 -> 1 | L31: ='Paramount Propack Private Limit'!M6 -> 18 | M31: ='Paramount Propack Private Limit'!N6 -> 1 | N31: ='Paramount Propack Private Limit'!O6 -> 17 | O31: ='Paramount Propack Private Limit'!P6 -> 9h 12m
A32: ="SANSAR TRADELINK" -> SANSAR TRADELINK | B32: ='Sansar Tradelink'!A5 -> AKASH PARMAR | C32: ='Sansar Tradelink'!B5 -> 30 | D32: ='Sansar Tradelink'!C5 -> 22 | E32: ='Sansar Tradelink'!D5 -> 0 | F32: ='Sansar Tradelink'!E5 -> 0 | G32: ='Sansar Tradelink'!F5 -> 2 | H32: ='Sansar Tradelink'!G5 -> 2 | I32: ='Sansar Tradelink'!H5 -> 0 | ... K32: ='Sansar Tradelink'!J5 -> 1 | L32: ='Sansar Tradelink'!M5 -> 20.5 | M32: ='Sansar Tradelink'!N5 -> 2 | N32: ='Sansar Tradelink'!O5 -> 18.5 | O32: ='Sansar Tradelink'!P5 -> 9h 6m
A33: ="SANSAR TRADELINK" -> SANSAR TRADELINK | B33: ='Sansar Tradelink'!A6 -> BHOOMI MISTRY | C33: ='Sansar Tradelink'!B6 -> 30 | D33: ='Sansar Tradelink'!C6 -> 22.5 | E33: ='Sansar Tradelink'!D6 -> 0 | F33: ='Sansar Tradelink'!E6 -> 1 | G33: ='Sansar Tradelink'!F6 -> 1 | H33: ='Sansar Tradelink'!G6 -> 1.5 | I33: ='Sansar Tradelink'!H6 -> 0 | ... K33: ='Sansar Tradelink'!J6 -> 1 | L33: ='Sansar Tradelink'!M6 -> 21 | M33: ='Sansar Tradelink'!N6 -> 1.5 | N33: ='Sansar Tradelink'!O6 -> 19.5 | O33: ='Sansar Tradelink'!P6 -> 9h 6m
A34: ="SANSAR TRADELINK" -> SANSAR TRADELINK | B34: ='Sansar Tradelink'!A7 -> DEEPIKA MAKWANA | C34: ='Sansar Tradelink'!B7 -> 30 | D34: ='Sansar Tradelink'!C7 -> 19.5 | E34: ='Sansar Tradelink'!D7 -> 0 | F34: ='Sansar Tradelink'!E7 -> 1 | G34: ='Sansar Tradelink'!F7 -> 5 | H34: ='Sansar Tradelink'!G7 -> 5.5 | I34: ='Sansar Tradelink'!H7 -> 0 | ... K34: ='Sansar Tradelink'!J7 -> 0 | L34: ='Sansar Tradelink'!M7 -> 18.5 | M34: ='Sansar Tradelink'!N7 -> 5.5 | N34: ='Sansar Tradelink'!O7 -> 13 | O34: ='Sansar Tradelink'!P7 -> 8h 54m
A35: ="SANSAR TRADELINK" -> SANSAR TRADELINK | B35: ='Sansar Tradelink'!A8 -> DIXITA SEVRA | C35: ='Sansar Tradelink'!B8 -> 30 | D35: ='Sansar Tradelink'!C8 -> 20 | E35: ='Sansar Tradelink'!D8 -> 0 | F35: ='Sansar Tradelink'!E8 -> 0 | G35: ='Sansar Tradelink'!F8 -> 6 | H35: ='Sansar Tradelink'!G8 -> 6 | I35: ='Sansar Tradelink'!H8 -> 0 | ... K35: ='Sansar Tradelink'!J8 -> 0 | L35: ='Sansar Tradelink'!M8 -> 13.5 | M35: ='Sansar Tradelink'!N8 -> 6 | N35: ='Sansar Tradelink'!O8 -> 7.5 | O35: ='Sansar Tradelink'!P8 -> 9h 0m
A36: ="SANSAR TRADELINK" -> SANSAR TRADELINK | B36: ='Sansar Tradelink'!A9 -> HIMANSHU SINGH | C36: ='Sansar Tradelink'!B9 -> 29.5 | D36: ='Sansar Tradelink'!C9 -> 23.5 | E36: ='Sansar Tradelink'!D9 -> 0.5 | F36: ='Sansar Tradelink'!E9 -> 0 | G36: ='Sansar Tradelink'!F9 -> 0 | H36: ='Sansar Tradelink'!G9 -> 0 | I36: ='Sansar Tradelink'!H9 -> 0 | ... K36: ='Sansar Tradelink'!J9 -> 1 | L36: ='Sansar Tradelink'!M9 -> 24.5 | M36: ='Sansar Tradelink'!N9 -> 0 | N36: ='Sansar Tradelink'!O9 -> 24.5 | O36: ='Sansar Tradelink'!P9 -> 9h 24m
A37: ="SANSAR TRADELINK" -> SANSAR TRADELINK | B37: ='Sansar Tradelink'!A10 -> JAY KACHA | C37: ='Sansar Tradelink'!B10 -> 30 | D37: ='Sansar Tradelink'!C10 -> 23 | E37: ='Sansar Tradelink'!D10 -> 0 | F37: ='Sansar Tradelink'!E10 -> 0 | G37: ='Sansar Tradelink'!F10 -> 2 | H37: ='Sansar Tradelink'!G10 -> 2 | I37: ='Sansar Tradelink'!H10 -> 0 | ... K37: ='Sansar Tradelink'!J10 -> 0 | L37: ='Sansar Tradelink'!M10 -> 14.5 | M37: ='Sansar Tradelink'!N10 -> 2 | N37: ='Sansar Tradelink'!O10 -> 12.5 | O37: ='Sansar Tradelink'!P10 -> 9h 6m
A38: ="SANSAR TRADELINK" -> SANSAR TRADELINK | B38: ='Sansar Tradelink'!A11 -> JEEVAN DRAVID | C38: ='Sansar Tradelink'!B11 -> 30 | D38: ='Sansar Tradelink'!C11 -> 22 | E38: ='Sansar Tradelink'!D11 -> 0 | F38: ='Sansar Tradelink'!E11 -> 0 | G38: ='Sansar Tradelink'!F11 -> 2 | H38: ='Sansar Tradelink'!G11 -> 2 | I38: ='Sansar Tradelink'!H11 -> 0 | ... K38: ='Sansar Tradelink'!J11 -> 1 | L38: ='Sansar Tradelink'!M11 -> 16 | M38: ='Sansar Tradelink'!N11 -> 2 | N38: ='Sansar Tradelink'!O11 -> 14 | O38: ='Sansar Tradelink'!P11 -> 9h 18m
A39: ="SANSAR TRADELINK" -> SANSAR TRADELINK | B39: ='Sansar Tradelink'!A12 -> JIMMY MAKWANA | C39: ='Sansar Tradelink'!B12 -> 29 | D39: ='Sansar Tradelink'!C12 -> 23 | E39: ='Sansar Tradelink'!D12 -> 0 | F39: ='Sansar Tradelink'!E12 -> 0 | G39: ='Sansar Tradelink'!F12 -> 0 | H39: ='Sansar Tradelink'!G12 -> 0 | I39: ='Sansar Tradelink'!H12 -> 1 | ... K39: ='Sansar Tradelink'!J12 -> 1 | L39: ='Sansar Tradelink'!M12 -> 0 | M39: ='Sansar Tradelink'!N12 -> 0 | N39: ='Sansar Tradelink'!O12 -> 0 | O39: ='Sansar Tradelink'!P12 -> 9h 42m
A40: ="SANSAR TRADELINK" -> SANSAR TRADELINK | B40: ='Sansar Tradelink'!A13 -> MANOJ ADIDRAVID | C40: ='Sansar Tradelink'!B13 -> 29 | D40: ='Sansar Tradelink'!C13 -> 23 | E40: ='Sansar Tradelink'!D13 -> 0 | F40: ='Sansar Tradelink'!E13 -> 0 | G40: ='Sansar Tradelink'!F13 -> 0 | H40: ='Sansar Tradelink'!G13 -> 0 | I40: ='Sansar Tradelink'!H13 -> 1 | ... K40: ='Sansar Tradelink'!J13 -> 1 | L40: ='Sansar Tradelink'!M13 -> 10 | M40: ='Sansar Tradelink'!N13 -> 0 | N40: ='Sansar Tradelink'!O13 -> 10 | O40: ='Sansar Tradelink'!P13 -> 8h 48m
A41: ="SANSAR TRADELINK" -> SANSAR TRADELINK | B41: ='Sansar Tradelink'!A14 -> PARTH SOLANKI | C41: ='Sansar Tradelink'!B14 -> 30 | D41: ='Sansar Tradelink'!C14 -> 24 | E41: ='Sansar Tradelink'!D14 -> 0 | F41: ='Sansar Tradelink'!E14 -> 0 | G41: ='Sansar Tradelink'!F14 -> 1 | H41: ='Sansar Tradelink'!G14 -> 1 | I41: ='Sansar Tradelink'!H14 -> 0 | ... K41: ='Sansar Tradelink'!J14 -> 1 | L41: ='Sansar Tradelink'!M14 -> 40.5 | M41: ='Sansar Tradelink'!N14 -> 1 | N41: ='Sansar Tradelink'!O14 -> 39.5 | O41: ='Sansar Tradelink'!P14 -> 9h 12m
A42: ="SANSAR TRADELINK" -> SANSAR TRADELINK | B42: ='Sansar Tradelink'!A15 -> SRUTHI NAIR | C42: ='Sansar Tradelink'!B15 -> 30 | D42: ='Sansar Tradelink'!C15 -> 20 | E42: ='Sansar Tradelink'!D15 -> 0 | F42: ='Sansar Tradelink'!E15 -> 0 | G42: ='Sansar Tradelink'!F15 -> 4 | H42: ='Sansar Tradelink'!G15 -> 4 | I42: ='Sansar Tradelink'!H15 -> 0 | ... K42: ='Sansar Tradelink'!J15 -> 1 | L42: ='Sansar Tradelink'!M15 -> 19.5 | M42: ='Sansar Tradelink'!N15 -> 4 | N42: ='Sansar Tradelink'!O15 -> 15.5 | O42: ='Sansar Tradelink'!P15 -> 8h 54m
...

Sheet Alluvium IoT Solutions Private 
A1: ALLUVIUM IOT SOLUTIONS PRIVATE LIMITED — ATTENDANCE & LEAVE REGISTER
A2: Period: 01 Sep 2026 to 30 Sep 2026 | Generated on: 16-Oct-2026 14:53 | Staff Count: 2
A4: Employee | B4: Total Working Days | C4: Present | D4: Absent | E4: Half Day PL | F4: Full Day PL | G4: Total PL Taken | H4: LWP Taken | I4: Week Off | J4: Holiday | M4: September Opening Balance | N4: PL Taken | O4: Available Balance | P4: Avg Hours/Day
A5: ARPIT SINGHAL | B5: 0 | C5: 0 | D5: 26 | E5: 0 | F5: 0 | G5: 0 | H5: 4 | I5: 0 | J5: 0 | M5: 0 | N5: 0 | O5: 0 | P5: 0h 0m
A6: MASOOD RAZA | B6: 30 | C6: 21 | D6: 0 | E6: 0 | F6: 2 | G6: 2 | H6: 0 | I6: 6 | J6: 1 | M6: 10 | N6: 2 | O6: 8 | P6: 9h 48m
A9: DAILY LOGS: ARPIT SINGHAL
A10: Date | B10: Day | C10: Shift | D10: Status | E10: In Time | F10: Out Time | G10: Total Hours | H10: Late In / Early Out
A11: 01-09-2026 | B11: Tue | C11: — | D11: Absent | H11: —
A12: 02-09-2026 | B12: Wed | C12: — | D12: Absent | H12: —
A13: 03-09-2026 | B13: Thu | C13: — | D13: Absent | H13: —
A14: 04-09-2026 | B14: Fri | C14: — | D14: Absent | H14: —
A15: 05-09-2026 | B15: Sat | C15: — | D15: Absent | H15: —
A16: 06-09-2026 | B16: Sun | C16: — | D16: LWP | H16: —
A17: 07-09-2026 | B17: Mon | C17: — | D17: Absent | H17: —
A18: 08-09-2026 | B18: Tue | C18: — | D18: Absent | H18: —
A19: 09-09-2026 | B19: Wed | C19: — | D19: Absent | H19: —
A20: 10-09-2026 | B20: Thu | C20: — | D20: Absent | H20: —
A21: 11-09-2026 | B21: Fri | C21: — | D21: Absent | H21: —
A22: 12-09-2026 | B22: Sat | C22: — | D22: Absent | H22: —
... A40: 30-09-2026 | B40: Wed | C40: — | D40: Absent | H40: —
A41: Total Worked Hours | G41: 0h 0m
A43: DAILY LOGS: MASOOD RAZA
A44: Date | B44: Day | C44: Shift | D44: Status | E44: In Time | F44: Out Time | G44: Total Hours | H44: Late In / Early Out
A45: 01-09-2026 | B45: Tue | C45: SFPL-10-7 10:00–19:00 | D45: Present | E45: 8:57 AM | F45: 6:30 PM | G45: 9h 33m | H45: Early Out (29m)
A46: 02-09-2026 | B46: Wed | C46: SFPL-10-7 10:00–19:00 | D46: Present | E46: 9:28 AM | F46: 7:56 PM | G46: 10h 28m | H46: On Time
A47: 03-09-2026 | B47: Thu | C47: SFPL-10-7 10:00–19:00 | D47: Present | E47: 9:13 AM | F47: 6:30 PM | G47: 9h 17m | H47: Early Out (30m)
A48: 04-09-2026 | B48: Fri | C48: SFPL-10-7 10:00–19:00 | D48: Holiday | H48: —
A49: 05-09-2026 | B49: Sat | C49: SFPL-10-7 10:00–19:00 | D49: Present | E49: 8:42 AM | F49: 7:40 PM | G49: 10h 58m | H49: On Time
A50: 06-09-2026 | B50: Sun | C50: SFPL-10-7 10:00–19:00 | D50: Weekly Off | H50: —
A51: 07-09-2026 | B51: Mon | C51: SFPL-10-7 10:00–19:00 | D51: PL | H51: —
A52: 08-09-2026 | B52: Tue | C52: SFPL-10-7 10:00–19:00 | D52: Present | E52: 2:43 PM | F52: 4:28 PM | G52: 1h 45m | H52: Late In (283m), Early Out (152m)
A53: 09-09-2026 | B53: Wed | C53: SFPL-10-7 10:00–19:00 | D53: Present | E53: 9:04 AM | F53: 8:58 PM | G53: 11h 53m | H53: On Time
A54: 10-09-2026 | B54: Thu | C54: SFPL-10-7 10:00–19:00 | D54: Present | E54: 9:00 AM | F54: 7:51 PM | G54: 10h 51m | H54: On Time
A55: 11-09-2026 | B55: Fri | C55: SFPL-10-7 10:00–19:00 | D55: Present | E55: 9:00 AM | F55: 6:00 PM | G55: 9h 0m | H55: Early Out (60m)
A56: 12-09-2026 | B56: Sat | C56: SFPL-10-7 10:00–19:00 | D56: Weekly Off | H56: —
A57: 13-09-2026 | B57: Sun | C57: SFPL-10-7 10:00–19:00 | D57: Weekly Off | H57: —
A58: 14-09-2026 | B58: Mon | C58: SFPL-10-7 10:00–19:00 | D58: PL | H58: —
A59: 15-09-2026 | B59: Tue | C59: SFPL-10-7 10:00–19:00 | D59: Present | E59: 9:10 AM | F59: 9:06 PM | G59: 11h 56m | H59: On Time
A60: 16-09-2026 | B60: Wed | C60: SFPL-10-7 10:00–19:00 | D60: Present | E60: 9:13 AM | F60: 8:03 PM | G60: 10h 50m | H60: On Time
A61: 17-09-2026 | B61: Thu | C61: SFPL-10-7 10:00–19:00 | D61: Present | E61: 9:21 AM | F61: 7:59 PM | G61: 10h 38m | H61: On Time
...

Sheet Eximbiz Enterprise
A1: EXIMBIZ ENTERPRISE — ATTENDANCE & LEAVE REGISTER
A2: Period: 01 Sep 2026 to 30 Sep 2026 | Generated on: 16-Oct-2026 14:53 | Staff Count: 8
A4: Employee | B4: Total Working Days | C4: Present | D4: Absent | E4: Half Day PL | F4: Full Day PL | G4: Total PL Taken | H4: LWP Taken | I4: Week Off | J4: Holiday | M4: September Opening Balance | N4: PL Taken | O4: Available Balance | P4: Avg Hours/Day
A5: AHMED ADENWALA | B5: 30 | C5: 23.5 | D5: 0 | E5: 1 | F5: 0 | G5: 0.5 | H5: 0 | I5: 5 | J5: 1 | M5: 35.5 | N5: 0.5 | O5: 35 | P5: 9h 12m
A6: ALPESH PARMAR | B6: 30 | C6: 20 | D6: 0 | E6: 2 | F6: 3 | G6: 4 | H6: 0 | I6: 5 | J6: 1 | M6: 24.5 | N6: 4 | O6: 20.5 | P6: 9h 0m
A7: AMBILY | B7: 30 | C7: 24 | D7: 0 | E7: 0 | F7: 0 | G7: 0 | H7: 0 | I7: 5 | J7: 1 | M7: 0 | N7: 0 | O7: 0 | P7: 9h 0m
A8: DIPAK VAGHELA | B8: 30 | C8: 20.5 | D8: 0 | E8: 5 | F8: 2 | G8: 4.5 | H8: 0 | I8: 4 | J8: 1 | M8: 16 | N8: 4.5 | O8: 11.5 | P8: 9h 30m
A9: HIRANRAJ R | B9: 30 | C9: 24 | D9: 0 | E9: 0 | F9: 0 | G9: 0 | H9: 0 | I9: 5 | J9: 1 | M9: 0 | N9: 0 | O9: 0 | P9: 9h 6m
A10: KARAN MISHRA | B10: 30 | C10: 22 | D10: 0 | E10: 0 | F10: 2 | G10: 2 | H10: 0 | I10: 5 | J10: 1 | M10: 17 | N10: 2 | O10: 15 | P10: 9h 6m
A11: RAHUL SOLANKI | B11: 30 | C11: 23 | D11: 0 | E11: 0 | F11: 1 | G11: 1 | H11: 0 | I11: 5 | J11: 1 | M11: 31 | N11: 1 | O11: 30 | P11: 9h 6m
A12: RENUKA SONAVANE | B12: 30 | C12: 24 | D12: 0 | E12: 0 | F12: 0 | G12: 0 | H12: 0 | I12: 5 | J12: 1 | M12: 0 | N12: 0 | O12: 0 | P12: 9h 24m
A15: DAILY LOGS: AHMED ADENWALA
A16: Date | B16: Day | C16: Shift | D16: Status | E16: In Time | F16: Out Time | G16: Total Hours | H16: Late In / Early Out
A17: 01-09-2026 | B17: Tue | C17: SFPL-10-7 10:00–19:00 | D17: Present | E17: 10:40 AM | F17: 7:36 PM | G17: 8h 56m | H17: Late In (40m)
A18: 02-09-2026 | B18: Wed | C18: SFPL-10-7 10:00–19:00 | D18: Present | E18: 10:52 AM | F18: 7:58 PM | G18: 9h 6m | H18: Late In (52m)
A19: 03-09-2026 | B19: Thu | C19: SFPL-10-7 10:00–19:00 | D19: Present | E19: 10:36 AM | F19: 7:43 PM | G19: 9h 7m | H19: Late In (36m)
A20: 04-09-2026 | B20: Fri | C20: SFPL-10-7 10:00–19:00 | D20: Holiday | H20: —
A21: 05-09-2026 | B21: Sat | C21: SFPL-10-7 10:00–19:00 | D21: Present | E21: 10:47 AM | F21: 7:38 PM | G21: 8h 51m | H21: Late In (47m)
A22: 06-09-2026 | B22: Sun | C22: SFPL-10-7 10:00–19:00 | D22: Weekly Off | H22: —
A23: 07-09-2026 | B23: Mon | C23: SFPL-10-7 10:00–19:00 | D23: Present | E23: 10:53 AM | F23: 7:59 PM | G23: 9h 6m | H23: Late In (53m)
A24: 08-09-2026 | B24: Tue | C24: SFPL-10-7 10:00–19:00 | D24: Present | E24: 10:46 AM | F24: 7:45 PM | G24: 8h 59m | H24: Late In (46m)
A25: 09-09-2026 | B25: Wed | C25: SFPL-10-7 10:00–19:00 | D25: Present | E25: 10:41 AM | F25: 7:38 PM | G25: 8h 58m | H25: Late In (41m)
A26: 10-09-2026 | B26: Thu | C26: SFPL-10-7 10:00–19:00 | D26: Present | E26: 10:43 AM | F26: 7:59 PM | G26: 9h 16m | H26: Late In (43m)
A27: 11-09-2026 | B27: Fri | C27: SFPL-10-7 10:00–19:00 | D27: Present | E27: 10:43 AM | F27: 7:47 PM | G27: 9h 4m | H27: Late In (43m)
A28: 12-09-2026 | B28: Sat | C28: SFPL-10-7 10:00–19:00 | D28: Weekly Off | H28: —
A29: 13-09-2026 | B29: Sun | C29: SFPL-10-7 10:00–19:00 | D29: Weekly Off | H29: —
A30: 14-09-2026 | B30: Mon | C30: SFPL-10-7 10:00–19:00 | D30: Present | E30: 10:58 AM | F30: 7:28 PM | G30: 8h 30m | H30: Late In (58m)
A31: 15-09-2026 | B31: Tue | C31: SFPL-10-7 10:00–19:00 | D31: Present | E31: 10:48 AM | F31: 7:41 PM | G31: 8h 53m | H31: Late In (48m)
A32: 16-09-2026 | B32: Wed | C32: SFPL-10-7 10:00–19:00 | D32: Present | E32: 10:30 AM | F32: 7:58 PM | G32: 9h 28m | H32: Late In (30m)
A33: 17-09-2026 | B33: Thu | C33: SFPL-10-7 10:00–19:00 | D33: Present | E33: 10:42 AM | F33: 7:50 PM | G33: 9h 9m | H33: Late In (42m)
A34: 18-09-2026 | B34: Fri | C34: SFPL-10-7 10:00–19:00 | D34: Present | E34: 10:55 AM | F34: 8:04 PM | G34: 9h 9m | H34: Late In (55m)
A35: 19-09-2026 | B35: Sat | C35: SFPL-10-7 10:00–19:00 | D35: Present | E35: 10:48 AM | H35: Late In (48m)
A36: 20-09-2026 | B36: Sun | C36: SFPL-10-7 10:00–19:00 | D36: Weekly Off | H36: —
A37: 21-09-2026 | B37: Mon | C37: SFPL-10-7 10:00–19:00 | D37: Present | E37: 10:29 AM | H37: Late In (29m)
A38: 22-09-2026 | B38: Tue | C38: SFPL-10-7 10:00–19:00 | D38: Present | E38: 10:35 AM | F38: 8:08 PM | G38: 9h 32m | H38: Late In (35m)
A39: 23-09-2026 | B39: Wed | C39: SFPL-10-7 10:00–19:00 | D39: Present | E39: 10:45 AM | F39: 7:59 PM | G39: 9h 13m | H39: Late In (45m)
A40: 24-09-2026 | B40: Thu | C40: SFPL-10-7 10:00–19:00 | D40: Present | E40: 10:44 AM | F40: 7:57 PM | G40: 9h 13m | H40: Late In (44m)
A41: 25-09-2026 | B41: Fri | C41: SFPL-10-7 10:00–19:00 | D41: Present | E41: 10:48 AM | F41: 7:52 PM | G41: 9h 4m | H41: Late In (48m)
A42: 26-09-2026 | B42: Sat | C42: SFPL-10-7 10:00–19:00 | D42: Present | E42: 10:51 AM | F42: 7:37 PM | G42: 8h 46m | H42: Late In (51m)
A43: 27-09-2026 | B43: Sun | C43: SFPL-10-7 10:00–19:00 | D43: Weekly Off | H43: —
...

Sheet Novusha Consulting Services Ind
A1: NOVUSHA CONSULTING SERVICES INDIA LLP — ATTENDANCE & LEAVE REGISTER
A2: Period: 01 Sep 2026 to 30 Sep 2026 | Generated on: 16-Oct-2026 14:53 | Staff Count: 13
A4: Employee | B4: Total Working Days | C4: Present | D4: Absent | E4: Half Day PL | F4: Full Day PL | G4: Total PL Taken | H4: LWP Taken | I4: Week Off | J4: Holiday | M4: September Opening Balance | N4: PL Taken | O4: Available Balance | P4: Avg Hours/Day
A5: ANUBHAV SINGH | B5: 29 | C5: 22 | D5: 0 | E5: 0 | F5: 0 | G5: 0 | H5: 1 | I5: 6 | J5: 1 | M5: 17 | N5: 0 | O5: 17 | P5: 9h 6m
A6: ATUL NAGOSE | B6: 30 | C6: 22 | D6: 0 | E6: 0 | F6: 1 | G6: 1 | H6: 0 | I6: 6 | J6: 1 | M6: 20.5 | N6: 1 | O6: 19.5 | P6: 9h 0m
A7: JAGDISH PUROHIT | B7: 30 | C7: 12 | D7: 0 | E7: 0 | F7: 14 | G7: 14 | H7: 0 | I7: 3 | J7: 1 | M7: 14 | N7: 14 | O7: 0 | P7: 8h 48m
A8: KINJAL KHATRI | B8: 30 | C8: 22 | D8: 0 | E8: 0 | F8: 1 | G8: 1 | H8: 0 | I8: 6 | J8: 1 | M8: 17.5 | N8: 1 | O8: 16.5 | P8: 9h 0m
A9: KRUPALI BUSA | B9: 30 | C9: 22 | D9: 0 | E9: 0 | F9: 1 | G9: 1 | H9: 0 | I9: 6 | J9: 1 | M9: 13 | N9: 1 | O9: 12 | P9: 9h 0m
A10: NIRALI SHAH | B10: 0 | C10: 0 | D10: 26 | E10: 0 | F10: 0 | G10: 0 | H10: 4 | I10: 0 | J10: 0 | M10: 0 | N10: 0 | O10: 0 | P10: 0h 0m
A11: PRADEEP KUMAR SINGH | B11: 30 | C11: 23 | D11: 0 | E11: 0 | F11: 0 | G11: 0 | H11: 0 | I11: 6 | J11: 1 | M11: 0 | N11: 0 | O11: 0 | P11: 9h 18m
A12: PUNIT PANDEY | B12: 30 | C12: 23 | D12: 0 | E12: 0 | F12: 1 | G12: 1 | H12: 0 | I12: 5 | J12: 1 | M12: 13 | N12: 1 | O12: 12 | P12: 9h 12m
A13: RAUF DAYMA | B13: 30 | C13: 23 | D13: 0 | E13: 0 | F13: 0 | G13: 0 | H13: 0 | I13: 6 | J13: 1 | M13: 23 | N13: 0 | O13: 23 | P13: 9h 12m
A14: RIYA SAINI | B14: 0 | C14: 0 | D14: 26 | E14: 0 | F14: 0 | G14: 0 | H14: 4 | I14: 0 | J14: 0 | M14: 0 | N14: 0 | O14: 0 | P14: 0h 0m
A15: SAIF ANSARI | B15: 29 | C15: 22 | D15: 0 | E15: 0 | F15: 0 | G15: 0 | H15: 1 | I15: 6 | J15: 1 | M15: 0 | N15: 0 | O15: 0 | P15: 8h 54m
A16: SHIPRA TRIPATHI | B16: 30 | C16: 22 | D16: 0 | E16: 2 | F16: 0 | G16: 1 | H16: 0 | I16: 6 | J16: 1 | M16: 8 | N16: 1 | O16: 7 | P16: 9h 6m
A17: YASH GUPTA | B17: 30 | C17: 19 | D17: 0 | E17: 2 | F17: 3 | G17: 4 | H17: 0 | I17: 6 | J17: 1 | M17: 11 | N17: 4 | O17: 7 | P17: 9h 12m
A20: DAILY LOGS: ANUBHAV SINGH
A21: Date | B21: Day | C21: Shift | D21: Status | E21: In Time | F21: Out Time | G21: Total Hours | H21: Late In / Early Out
A22: 01-09-2026 | B22: Tue | C22: SFPL-10-7 10:00–19:00 | D22: Present | E22: 9:52 AM | F22: 6:53 PM | G22: 9h 1m | H22: On Time
A23: 02-09-2026 | B23: Wed | C23: SFPL-10-7 10:00–19:00 | D23: Present | E23: 9:51 AM | F23: 7:11 PM | G23: 9h 19m | H23: On Time
A24: 03-09-2026 | B24: Thu | C24: SFPL-10-7 10:00–19:00 | D24: Present | E24: 9:54 AM | F24: 7:03 PM | G24: 9h 9m | H24: On Time
A25: 04-09-2026 | B25: Fri | C25: SFPL-10-7 10:00–19:00 | D25: Holiday | H25: —
A26: 05-09-2026 | B26: Sat | C26: SFPL-10-7 10:00–19:00 | D26: Present | E26: 9:54 AM | F26: 6:55 PM | G26: 9h 1m | H26: On Time
A27: 06-09-2026 | B27: Sun | C27: SFPL-10-7 10:00–19:00 | D27: Weekly Off | H27: —
A28: 07-09-2026 | B28: Mon | C28: SFPL-10-7 10:00–19:00 | D28: Present | E28: 9:52 AM | F28: 7:03 PM | G28: 9h 11m | H28: On Time
A29: 08-09-2026 | B29: Tue | C29: SFPL-10-7 10:00–19:00 | D29: Present | E29: 9:58 AM | F29: 7:00 PM | G29: 9h 2m | H29: On Time
A30: 09-09-2026 | B30: Wed | C30: SFPL-10-7 10:00–19:00 | D30: Present | E30: 9:35 AM | F30: 6:48 PM | G30: 9h 12m | H30: On Time
A31: 10-09-2026 | B31: Thu | C31: SFPL-10-7 10:00–19:00 | D31: Present | E31: 9:39 AM | F31: 6:48 PM | G31: 9h 9m | H31: On Time
A32: 11-09-2026 | B32: Fri | C32: SFPL-10-7 10:00–19:00 | D32: Present | E32: 9:46 AM | F32: 6:47 PM | G32: 9h 1m | H32: On Time
A33: 12-09-2026 | B33: Sat | C33: SFPL-10-7 10:00–19:00 | D33: Weekly Off | H33: —
A34: 13-09-2026 | B34: Sun | C34: SFPL-10-7 10:00–19:00 | D34: Weekly Off | H34: —
A35: 14-09-2026 | B35: Mon | C35: SFPL-10-7 10:00–19:00 | D35: Present | E35: 10:30 AM | F35: 7:48 PM | G35: 9h 17m | H35: Late In (30m)
A36: 15-09-2026 | B36: Tue | C36: SFPL-10-7 10:00–19:00 | D36: Present | E36: 9:46 AM | F36: 6:57 PM | G36: 9h 12m | H36: On Time
A37: 16-09-2026 | B37: Wed | C37: SFPL-10-7 10:00–19:00 | D37: Present | E37: 10:01 AM | F37: 7:58 PM | G37: 9h 57m | H37: On Time
A38: 17-09-2026 | B38: Thu | C38: SFPL-10-7 10:00–19:00 | D38: Present | E38: 10:00 AM | F38: 7:02 PM | G38: 9h 2m | H38: On Time
A39: 18-09-2026 | B39: Fri | C39: SFPL-10-7 10:00–19:00 | D39: LWP | H39: —
A40: 19-09-2026 | B40: Sat | C40: SFPL-10-7 10:00–19:00 | D40: Present | E40: 9:45 AM | F40: 6:54 PM | G40: 9h 9m | H40: On Time
A41: 20-09-2026 | B41: Sun | C41: SFPL-10-7 10:00–19:00 | D41: Weekly Off | H41: —
A42: 21-09-2026 | B42: Mon | C42: SFPL-10-7 10:00–19:00 | D42: Present | E42: 9:44 AM | F42: 6:46 PM | G42: 9h 3m | H42: On Time
A43: 22-09-2026 | B43: Tue | C43: SFPL-10-7 10:00–19:00 | D43: Present | E43: 9:37 AM | F43: 6:38 PM | G43: 9h 0m | H43: Early Out (21m)
...

Sheet Paramount Propack Private Limit
A1: PARAMOUNT PROPACK PRIVATE LIMITED — ATTENDANCE & LEAVE REGISTER
A2: Period: 01 Sep 2026 to 30 Sep 2026 | Generated on: 16-Oct-2026 14:53 | Staff Count: 2
A4: Employee | B4: Total Working Days | C4: Present | D4: Absent | E4: Half Day PL | F4: Full Day PL | G4: Total PL Taken | H4: LWP Taken | I4: Week Off | J4: Holiday | M4: September Opening Balance | N4: PL Taken | O4: Available Balance | P4: Avg Hours/Day
A5: KRISHNAPAL PUVAR | B5: 0 | C5: 0 | D5: 24 | E5: 0 | F5: 0 | G5: 0 | H5: 6 | I5: 0 | J5: 0 | M5: 18.5 | N5: 0 | O5: 18.5 | P5: 0h 0m
A6: PRATIK SAKRECHA | B6: 30 | C6: 23 | D6: 0 | E6: 0 | F6: 1 | G6: 1 | H6: 0 | I6: 5 | J6: 1 | M6: 18 | N6: 1 | O6: 17 | P6: 9h 12m
A9: DAILY LOGS: KRISHNAPAL PUVAR
A10: Date | B10: Day | C10: Shift | D10: Status | E10: In Time | F10: Out Time | G10: Total Hours | H10: Late In / Early Out
A11: 01-09-2026 | B11: Tue | C11: SFPL-10-7 10:00–19:00 | D11: Absent | H11: —
A12: 02-09-2026 | B12: Wed | C12: SFPL-10-7 10:00–19:00 | D12: Absent | H12: —
A13: 03-09-2026 | B13: Thu | C13: SFPL-10-7 10:00–19:00 | D13: Absent | H13: —
A14: 04-09-2026 | B14: Fri | C14: SFPL-10-7 10:00–19:00 | D14: LWP | H14: —
A15: 05-09-2026 | B15: Sat | C15: SFPL-10-7 10:00–19:00 | D15: Absent | H15: —
A16: 06-09-2026 | B16: Sun | C16: SFPL-10-7 10:00–19:00 | D16: LWP | H16: —
A17: 07-09-2026 | B17: Mon | C17: SFPL-10-7 10:00–19:00 | D17: Absent | H17: —
A18: 08-09-2026 | B18: Tue | C18: SFPL-10-7 10:00–19:00 | D18: Absent | H18: —
A19: 09-09-2026 | B19: Wed | C19: SFPL-10-7 10:00–19:00 | D19: Absent | H19: —
A20: 10-09-2026 | B20: Thu | C20: SFPL-10-7 10:00–19:00 | D20: Absent | H20: —
A21: 11-09-2026 | B21: Fri | C21: SFPL-10-7 10:00–19:00 | D21: Absent | H21: —
A22: 12-09-2026 | B22: Sat | C22: SFPL-10-7 10:00–19:00 | D22: LWP | H22: —
... A40: 30-09-2026 | B40: Wed | C40: SFPL-10-7 10:00–19:00 | D40: Absent | H40: —
A41: Total Worked Hours | G41: 0h 0m
A43: DAILY LOGS: PRATIK SAKRECHA
A44: Date | B44: Day | C44: Shift | D44: Status | E44: In Time | F44: Out Time | G44: Total Hours | H44: Late In / Early Out
A45: 01-09-2026 | B45: Tue | C45: SFPL-10-7 10:00–19:00 | D45: Present | E45: 9:14 AM | F45: 6:33 PM | G45: 9h 20m | H45: Early Out (26m)
A46: 02-09-2026 | B46: Wed | C46: SFPL-10-7 10:00–19:00 | D46: Present | E46: 9:35 AM | F46: 7:04 PM | G46: 9h 29m | H46: On Time
A47: 03-09-2026 | B47: Thu | C47: SFPL-10-7 10:00–19:00 | D47: Present | E47: 9:04 AM | F47: 6:39 PM | G47: 9h 34m | H47: Early Out (20m)
A48: 04-09-2026 | B48: Fri | C48: SFPL-10-7 10:00–19:00 | D48: Holiday | H48: —
A49: 05-09-2026 | B49: Sat | C49: SFPL-10-7 10:00–19:00 | D49: Present | E49: 9:06 AM | F49: 5:59 PM | G49: 8h 52m | H49: Early Out (60m)
A50: 06-09-2026 | B50: Sun | C50: SFPL-10-7 10:00–19:00 | D50: Weekly Off | H50: —
A51: 07-09-2026 | B51: Mon | C51: SFPL-10-7 10:00–19:00 | D51: Present | E51: 9:09 AM | F51: 6:23 PM | G51: 9h 14m | H51: Early Out (36m)
A52: 08-09-2026 | B52: Tue | C52: SFPL-10-7 10:00–19:00 | D52: Present | E52: 9:15 AM | F52: 6:32 PM | G52: 9h 17m | H52: Early Out (27m)
A53: 09-09-2026 | B53: Wed | C53: SFPL-10-7 10:00–19:00 | D53: Present | E53: 9:03 AM | F53: 6:28 PM | G53: 9h 25m | H53: Early Out (31m)
A54: 10-09-2026 | B54: Thu | C54: SFPL-10-7 10:00–19:00 | D54: Present | E54: 9:10 AM | F54: 6:10 PM | G54: 9h 0m | H54: Early Out (49m)
A55: 11-09-2026 | B55: Fri | C55: SFPL-10-7 10:00–19:00 | D55: Present | E55: 9:18 AM | F55: 6:11 PM | G55: 8h 53m | H55: Early Out (48m)
A56: 12-09-2026 | B56: Sat | C56: SFPL-10-7 10:00–19:00 | D56: Weekly Off | H56: —
A57: 13-09-2026 | B57: Sun | C57: SFPL-10-7 10:00–19:00 | D57: Weekly Off | H57: —
A58: 14-09-2026 | B58: Mon | C58: SFPL-10-7 10:00–19:00 | D58: Present | E58: 9:21 AM | F58: 6:19 PM | G58: 8h 58m | H58: Early Out (40m)
A59: 15-09-2026 | B59: Tue | C59: SFPL-10-7 10:00–19:00 | D59: Present | E59: 9:20 AM | F59: 6:21 PM | G59: 9h 1m | H59: Early Out (39m)
A60: 16-09-2026 | B60: Wed | C60: SFPL-10-7 10:00–19:00 | D60: Present | E60: 9:28 AM | F60: 6:21 PM | G60: 8h 53m | H60: Early Out (38m)
A61: 17-09-2026 | B61: Thu | C61: SFPL-10-7 10:00–19:00 | D61: Present | E61: 9:21 AM | F61: 6:46 PM | G61: 9h 25m | H61: On Time
...

Sheet Sansar Tradelink
A1: SANSAR TRADELINK — ATTENDANCE & LEAVE REGISTER
A2: Period: 01 Sep 2026 to 30 Sep 2026 | Generated on: 16-Oct-2026 14:53 | Staff Count: 11
A4: Employee | B4: Total Working Days | C4: Present | D4: Absent | E4: Half Day PL | F4: Full Day PL | G4: Total PL Taken | H4: LWP Taken | I4: Week Off | J4: Holiday | M4: September Opening Balance | N4: PL Taken | O4: Available Balance | P4: Avg Hours/Day
A5: AKASH PARMAR | B5: 30 | C5: 22 | D5: 0 | E5: 0 | F5: 2 | G5: 2 | H5: 0 | I5: 5 | J5: 1 | M5: 20.5 | N5: 2 | O5: 18.5 | P5: 9h 6m
A6: BHOOMI MISTRY | B6: 30 | C6: 22.5 | D6: 0 | E6: 1 | F6: 1 | G6: 1.5 | H6: 0 | I6: 5 | J6: 1 | M6: 21 | N6: 1.5 | O6: 19.5 | P6: 9h 6m
A7: DEEPIKA MAKWANA | B7: 30 | C7: 19.5 | D7: 0 | E7: 1 | F7: 5 | G7: 5.5 | H7: 0 | I7: 5 | J7: 0 | M7: 18.5 | N7: 5.5 | O7: 13 | P7: 8h 54m
A8: DIXITA SEVRA | B8: 30 | C8: 20 | D8: 0 | E8: 0 | F8: 6 | G8: 6 | H8: 0 | I8: 4 | J8: 0 | M8: 13.5 | N8: 6 | O8: 7.5 | P8: 9h 0m
A9: HIMANSHU SINGH | B9: 29.5 | C9: 23.5 | D9: 0.5 | E9: 0 | F9: 0 | G9: 0 | H9: 0 | I9: 5 | J9: 1 | M9: 24.5 | N9: 0 | O9: 24.5 | P9: 9h 24m
A10: JAY KACHA | B10: 30 | C10: 23 | D10: 0 | E10: 0 | F10: 2 | G10: 2 | H10: 0 | I10: 5 | J10: 0 | M10: 14.5 | N10: 2 | O10: 12.5 | P10: 9h 6m
A11: JEEVAN DRAVID | B11: 30 | C11: 22 | D11: 0 | E11: 0 | F11: 2 | G11: 2 | H11: 0 | I11: 5 | J11: 1 | M11: 16 | N11: 2 | O11: 14 | P11: 9h 18m
A12: JIMMY MAKWANA | B12: 29 | C12: 23 | D12: 0 | E12: 0 | F12: 0 | G12: 0 | H12: 1 | I12: 5 | J12: 1 | M12: 0 | N12: 0 | O12: 0 | P12: 9h 42m
A13: MANOJ ADIDRAVID | B13: 29 | C13: 23 | D13: 0 | E13: 0 | F13: 0 | G13: 0 | H13: 1 | I13: 5 | J13: 1 | M13: 10 | N13: 0 | O13: 10 | P13: 8h 48m
A14: PARTH SOLANKI | B14: 30 | C14: 24 | D14: 0 | E14: 0 | F14: 1 | G14: 1 | H14: 0 | I14: 4 | J14: 1 | M14: 40.5 | N14: 1 | O14: 39.5 | P14: 9h 12m
A15: SRUTHI NAIR | B15: 30 | C15: 20 | D15: 0 | E15: 0 | F15: 4 | G15: 4 | H15: 0 | I15: 5 | J15: 1 | M15: 19.5 | N15: 4 | O15: 15.5 | P15: 8h 54m
A18: DAILY LOGS: AKASH PARMAR
A19: Date | B19: Day | C19: Shift | D19: Status | E19: In Time | F19: Out Time | G19: Total Hours | H19: Late In / Early Out
A20: 01-09-2026 | B20: Tue | C20: SFPL-10-7 10:00–19:00 | D20: Present | E20: 8:29 AM | F20: 5:33 PM | G20: 9h 5m | H20: Early Out (86m)
A21: 02-09-2026 | B21: Wed | C21: SFPL-10-7 10:00–19:00 | D21: Present | E21: 8:27 AM | F21: 5:34 PM | G21: 9h 8m | H21: Early Out (85m)
A22: 03-09-2026 | B22: Thu | C22: SFPL-10-7 10:00–19:00 | D22: Present | E22: 8:30 AM | F22: 5:25 PM | G22: 8h 54m | H22: Early Out (94m)
A23: 04-09-2026 | B23: Fri | C23: SFPL-10-7 10:00–19:00 | D23: Holiday | H23: —
A24: 05-09-2026 | B24: Sat | C24: SFPL-10-7 10:00–19:00 | D24: PL | H24: —
A25: 06-09-2026 | B25: Sun | C25: SFPL-10-7 10:00–19:00 | D25: Weekly Off | H25: —
A26: 07-09-2026 | B26: Mon | C26: SFPL-10-7 10:00–19:00 | D26: Present | E26: 8:28 AM | F26: 5:33 PM | G26: 9h 5m | H26: Early Out (86m)
A27: 08-09-2026 | B27: Tue | C27: SFPL-10-7 10:00–19:00 | D27: Present | E27: 8:31 AM | F27: 5:37 PM | G27: 9h 7m | H27: Early Out (82m)
A28: 09-09-2026 | B28: Wed | C28: SFPL-10-7 10:00–19:00 | D28: Present | E28: 8:29 AM | F28: 5:31 PM | G28: 9h 2m | H28: Early Out (88m)
A29: 10-09-2026 | B29: Thu | C29: SFPL-10-7 10:00–19:00 | D29: Present | E29: 8:34 AM | F29: 5:35 PM | G29: 9h 1m | H29: Early Out (84m)
A30: 11-09-2026 | B30: Fri | C30: SFPL-10-7 10:00–19:00 | D30: Present | E30: 8:31 AM | F30: 5:31 PM | G30: 9h 0m | H30: Early Out (88m)
A31: 12-09-2026 | B31: Sat | C31: SFPL-10-7 10:00–19:00 | D31: Weekly Off | H31: —
A32: 13-09-2026 | B32: Sun | C32: SFPL-10-7 10:00–19:00 | D32: Weekly Off | H32: —
